<?xml version="1.0" ?>
<robot name="TurtleBot3Burger">
    <link name="base_link">
        <visual>
            <origin xyz="0 0 0" rpy="0 0 0"/>
            <geometry>
                <box size="0.140 0.140 0.143"/>
            </geometry>
        </visual>
        <collision>
            <origin xyz="0 0 0" rpy="0 0 0"/>
            <geometry>
                <box size="0.140 0.140 0.143"/>
            </geometry>
        </collision>
        <inertial>
            <mass value="1.0"/>
            <inertia ixx="0.01" ixy="0.0" ixz="0.0" iyy="0.01" iyz="0.0" izz="0.01"/>
        </inertial>
    </link>

    <link name="base_footprint"/>
    <joint name="base_joint" type="fixed">
        <parent link="base_link"/>
        <child link="base_footprint"/>
        <origin xyz="0 0 0" rpy="0 0 0"/>
    </joint>

    <link name="base_scan">
        <visual>
            <origin xyz="0 0 0" rpy="0 0 0"/>
            <geometry>
                <cylinder length="0.03" radius="0.03"/>
            </geometry>
        </visual>
    </link>
    <joint name="scan_joint" type="fixed">
        <parent link="base_link"/>
        <child link="base_scan"/>
        <origin xyz="0 0 0.08" rpy="0 0 0"/>
    </joint>

    <link name="wheel_left_link">
        <visual>
            <origin xyz="0 0 0" rpy="1.57 0 0"/>
            <geometry>
                <cylinder length="0.018" radius="0.033"/>
            </geometry>
        </visual>
        <collision>
            <origin xyz="0 0 0" rpy="1.57 0 0"/>
            <geometry>
                <cylinder length="0.018" radius="0.033"/>
            </geometry>
        </collision>
        <inertial>
            <mass value="0.1"/>
            <inertia ixx="0.001" ixy="0" ixz="0" iyy="0.001" iyz="0" izz="0.001"/>
        </inertial>
    </link>

    <joint name="wheel_left_joint" type="continuous">
        <parent link="base_link"/>
        <child link="wheel_left_link"/>
        <origin xyz="0.0 0.08 0.023" rpy="0 0 0"/>
        <axis xyz="0 1 0"/>
    </joint>

    <link name="wheel_right_link">
        <visual>
            <origin xyz="0 0 0" rpy="1.57 0 0"/>
            <geometry>
                <cylinder length="0.018" radius="0.033"/>
            </geometry>
        </visual>
        <collision>
            <origin xyz="0 0 0" rpy="1.57 0 0"/>
            <geometry>
                <cylinder length="0.018" radius="0.033"/>
            </geometry>
        </collision>
        <inertial>
            <mass value="0.1"/>
            <inertia ixx="0.001" ixy="0" ixz="0" iyy="0.001" iyz="0" izz="0.001"/>
        </inertial>
    </link>

    <joint name="wheel_right_joint" type="continuous">
        <parent link="base_link"/>
        <child link="wheel_right_link"/>
        <origin xyz="0.0 -0.08 0.023" rpy="0 0 0"/>
        <axis xyz="0 1 0"/>
    </joint>

    <link name="caster_back_link">
        <collision>
            <origin xyz="0 0.001 0" rpy="0 0 0"/>
            <geometry>
                <box size="0.030 0.009 0.020"/>
            </geometry>
        </collision>
    </link>
    <joint name="caster_back_joint" type="fixed">
        <parent link="base_link"/>
        <child link="caster_back_link"/>
        <origin xyz="-0.081 0 -0.004" rpy="0 0 0"/>
    </joint>

    <ros2_control name="WebotsControl" type="system">
        <hardware>
            <plugin>webots_ros2_control::Ros2ControlSystem</plugin>
        </hardware>
        
        <joint name="wheel_left_joint">
            <state_interface name="position"/>
            <state_interface name="velocity"/>  <command_interface name="velocity"/>
        </joint>
        
        <joint name="wheel_right_joint">
            <state_interface name="position"/>
            <state_interface name="velocity"/>  <command_interface name="velocity"/>
        </joint>
    </ros2_control>
</robot>