<?xml version="1.0"?>
<robot name="my_robot">
  <link name="base_link">
    <visual>
      <geometry>
        <box size="0.2 0.05 0.1"/>
      </geometry>
      <material name="blue"/>
    </visual>
  </link>

  <link name="left_wheel"/>
  <link name="right_wheel"/>

  <joint name="left_wheel_joint" type="continuous">
    <parent link="base_link"/>
    <child link="left_wheel"/>
  </joint>

  <joint name="right_wheel_joint" type="continuous">
    <parent link="base_link"/>
    <child link="right_wheel"/>
  </joint>

  <webots>
    <plugin type="webots_ros2_my_robot.my_robot_driver.my_robot_driver.MyRobotDriver" />
  </webots>
</robot>
